5:return {{["x"] = 0, ["y"] = 9, ["z"] = 0, ["name"] = "default:junglewood"}, {["x"] = 0, ["y"] = 9, ["z"] = 1, ["name"] = "default:junglewood"}, {["x"] = 0, ["y"] = 9, ["z"] = 2, ["name"] = "default:junglewood"}, {["x"] = 0, ["y"] = 9, ["z"] = 3, ["name"] = "default:junglewood"}, {["x"] = 0, ["y"] = 9, ["z"] = 4, ["name"] = "default:junglewood"}, {["x"] = 0, ["y"] = 9, ["z"] = 5, ["name"] = "default:junglewood"}, {["x"] = 0, ["y"] = 9, ["z"] = 6, ["name"] = "default:junglewood"}, {["x"] = 0, ["y"] = 9, ["z"] = 7, ["name"] = "default:junglewood"}, {["x"] = 0, ["y"] = 9, ["z"] = 8, ["name"] = "default:junglewood"}, {["x"] = 0, ["y"] = 9, ["z"] = 9, ["name"] = "default:junglewood"}, {["x"] = 0, ["y"] = 9, ["z"] = 10, ["name"] = "default:junglewood"}, {["x"] = 0, ["y"] = 9, ["z"] = 11, ["name"] = "default:junglewood"}, {["x"] = 0, ["y"] = 9, ["z"] = 12, ["name"] = "default:junglewood"}, {["x"] = 0, ["y"] = 9, ["z"] = 13, ["name"] = "default:junglewood"}, {["x"] = 0, ["y"] = 9, ["z"] = 14, ["name"] = "default:junglewood"}, {["x"] = 0, ["y"] = 9, ["z"] = 15, ["name"] = "default:junglewood"}, {["x"] = 0, ["y"] = 10, ["z"] = 0, ["name"] = "default:junglewood"}, {["x"] = 0, ["y"] = 10, ["z"] = 1, ["name"] = "default:junglewood"}, {["x"] = 0, ["y"] = 10, ["z"] = 2, ["name"] = "default:junglewood"}, {["x"] = 0, ["y"] = 10, ["z"] = 3, ["name"] = "default:junglewood"}, {["x"] = 0, ["y"] = 10, ["z"] = 4, ["name"] = "default:junglewood"}, {["x"] = 0, ["y"] = 10, ["z"] = 5, ["name"] = "default:junglewood"}, {["x"] = 0, ["y"] = 10, ["z"] = 6, ["name"] = "default:junglewood"}, {["x"] = 0, ["y"] = 10, ["z"] = 7, ["name"] = "default:junglewood"}, {["x"] = 0, ["y"] = 10, ["z"] = 8, ["name"] = "default:junglewood"}, {["x"] = 0, ["y"] = 10, ["z"] = 9, ["name"] = "default:junglewood"}, {["x"] = 0, ["y"] = 10, ["z"] = 10, ["name"] = "default:junglewood"}, {["x"] = 0, ["y"] = 10, ["z"] = 11, ["name"] = "default:junglewood"}, {["x"] = 0, ["y"] = 10, ["z"] = 12, ["name"] = "default:junglewood"}, {["x"] = 0, ["y"] = 10, ["z"] = 13, ["name"] = "default:junglewood"}, {["x"] = 0, ["y"] = 10, ["z"] = 14, ["name"] = "default:junglewood"}, {["x"] = 0, ["y"] = 10, ["z"] = 15, ["name"] = "default:junglewood"}, {["x"] = 1, ["y"] = 0, ["z"] = 1, ["name"] = "default:wood"}, {["x"] = 1, ["y"] = 0, ["z"] = 2, ["name"] = "default:wood"}, {["x"] = 1, ["y"] = 0, ["z"] = 13, ["name"] = "default:wood"}, {["x"] = 1, ["y"] = 0, ["z"] = 14, ["name"] = "default:wood"}, {["x"] = 1, ["y"] = 1, ["z"] = 1, ["name"] = "default:wood"}, {["x"] = 1, ["y"] = 1, ["z"] = 2, ["name"] = "default:wood"}, {["x"] = 1, ["y"] = 1, ["z"] = 13, ["name"] = "default:wood"}, {["x"] = 1, ["y"] = 1, ["z"] = 14, ["name"] = "default:wood"}, {["x"] = 1, ["y"] = 2, ["z"] = 1, ["name"] = "default:wood"}, {["x"] = 1, ["y"] = 2, ["z"] = 2, ["name"] = "default:wood"}, {["x"] = 1, ["y"] = 2, ["z"] = 13, ["name"] = "default:wood"}, {["x"] = 1, ["y"] = 2, ["z"] = 14, ["name"] = "default:wood"}, {["x"] = 1, ["y"] = 3, ["z"] = 1, ["name"] = "default:wood"}, {["x"] = 1, ["y"] = 3, ["z"] = 2, ["name"] = "default:wood"}, {["x"] = 1, ["y"] = 3, ["z"] = 13, ["name"] = "default:wood"}, {["x"] = 1, ["y"] = 3, ["z"] = 14, ["name"] = "default:wood"}, {["x"] = 1, ["y"] = 4, ["z"] = 1, ["name"] = "default:wood"}, {["x"] = 1, ["y"] = 4, ["z"] = 2, ["name"] = "default:wood"}, {["x"] = 1, ["y"] = 4, ["z"] = 13, ["name"] = "default:wood"}, {["x"] = 1, ["y"] = 4, ["z"] = 14, ["name"] = "default:wood"}, {["x"] = 1, ["y"] = 5, ["z"] = 1, ["name"] = "default:wood"}, {["x"] = 1, ["y"] = 5, ["z"] = 2, ["name"] = "default:wood"}, {["x"] = 1, ["y"] = 5, ["z"] = 13, ["name"] = "default:wood"}, {["x"] = 1, ["y"] = 5, ["z"] = 14, ["name"] = "default:wood"}, {["x"] = 1, ["y"] = 6, ["z"] = 1, ["name"] = "default:wood"}, {["x"] = 1, ["y"] = 6, ["z"] = 2, ["name"] = "default:wood"}, {["x"] = 1, ["y"] = 6, ["z"] = 13, ["name"] = "default:wood"}, {["x"] = 1, ["y"] = 6, ["z"] = 14, ["name"] = "default:wood"}, {["x"] = 1, ["y"] = 7, ["z"] = 1, ["name"] = "default:wood"}, {["x"] = 1, ["y"] = 7, ["z"] = 2, ["name"] = "default:wood"}, {["x"] = 1, ["y"] = 7, ["z"] = 13, ["name"] = "default:wood"}, {["x"] = 1, ["y"] = 7, ["z"] = 14, ["name"] = "default:wood"}, {["x"] = 1, ["y"] = 8, ["z"] = 1, ["name"] = "default:wood"}, {["x"] = 1, ["y"] = 8, ["z"] = 2, ["name"] = "default:wood"}, {["x"] = 1, ["y"] = 8, ["z"] = 13, ["name"] = "default:wood"}, {["x"] = 1, ["y"] = 8, ["z"] = 14, ["name"] = "default:wood"}, {["x"] = 1, ["y"] = 9, ["z"] = 0, ["name"] = "default:junglewood"}, {["x"] = 1, ["y"] = 9, ["z"] = 1, ["name"] = "default:wood"}, {["x"] = 1, ["y"] = 9, ["z"] = 2, ["name"] = "default:wood"}, {["x"] = 1, ["y"] = 9, ["z"] = 3, ["name"] = "default:junglewood"}, {["x"] = 1, ["y"] = 9, ["z"] = 4, ["name"] = "default:junglewood"}, {["x"] = 1, ["y"] = 9, ["z"] = 5, ["name"] = "default:junglewood"}, {["x"] = 1, ["y"] = 9, ["z"] = 6, ["name"] = "default:junglewood"}, {["x"] = 1, ["y"] = 9, ["z"] = 7, ["name"] = "default:junglewood"}, {["x"] = 1, ["y"] = 9, ["z"] = 8, ["name"] = "default:junglewood"}, {["x"] = 1, ["y"] = 9, ["z"] = 9, ["name"] = "default:junglewood"}, {["x"] = 1, ["y"] = 9, ["z"] = 10, ["name"] = "default:junglewood"}, {["x"] = 1, ["y"] = 9, ["z"] = 11, ["name"] = "default:junglewood"}, {["x"] = 1, ["y"] = 9, ["z"] = 12, ["name"] = "default:junglewood"}, {["x"] = 1, ["y"] = 9, ["z"] = 13, ["name"] = "default:wood"}, {["x"] = 1, ["y"] = 9, ["z"] = 14, ["name"] = "default:wood"}, {["x"] = 1, ["y"] = 9, ["z"] = 15, ["name"] = "default:junglewood"}, {["x"] = 1, ["y"] = 10, ["z"] = 0, ["name"] = "default:junglewood"}, {["x"] = 1, ["y"] = 10, ["z"] = 1, ["name"] = "default:junglewood"}, {["x"] = 1, ["y"] = 10, ["z"] = 2, ["name"] = "default:junglewood"}, {["x"] = 1, ["y"] = 10, ["z"] = 3, ["name"] = "default:junglewood"}, {["x"] = 1, ["y"] = 10, ["z"] = 4, ["name"] = "default:junglewood"}, {["x"] = 1, ["y"] = 10, ["z"] = 5, ["name"] = "default:junglewood"}, {["x"] = 1, ["y"] = 10, ["z"] = 6, ["name"] = "default:junglewood"}, {["x"] = 1, ["y"] = 10, ["z"] = 7, ["name"] = "default:junglewood"}, {["x"] = 1, ["y"] = 10, ["z"] = 8, ["name"] = "default:junglewood"}, {["x"] = 1, ["y"] = 10, ["z"] = 9, ["name"] = "default:junglewood"}, {["x"] = 1, ["y"] = 10, ["z"] = 10, ["name"] = "default:junglewood"}, {["x"] = 1, ["y"] = 10, ["z"] = 11, ["name"] = "default:junglewood"}, {["x"] = 1, ["y"] = 10, ["z"] = 12, ["name"] = "default:junglewood"}, {["x"] = 1, ["y"] = 10, ["z"] = 13, ["name"] = "default:junglewood"}, {["x"] = 1, ["y"] = 10, ["z"] = 14, ["name"] = "default:junglewood"}, {["x"] = 1, ["y"] = 10, ["z"] = 15, ["name"] = "default:junglewood"}, {["x"] = 1, ["y"] = 11, ["z"] = 7, ["name"] = "wool:green"}, {["x"] = 1, ["y"] = 11, ["z"] = 8, ["name"] = "wool:green"}, {["x"] = 1, ["y"] = 11, ["z"] = 9, ["name"] = "wool:green"}, {["x"] = 1, ["y"] = 11, ["z"] = 10, ["name"] = "wool:green"}, {["x"] = 1, ["y"] = 11, ["z"] = 11, ["name"] = "wool:green"}, {["x"] = 1, ["y"] = 11, ["z"] = 12, ["name"] = "wool:green"}, {["x"] = 1, ["y"] = 11, ["z"] = 13, ["name"] = "wool:green"}, {["x"] = 1, ["y"] = 11, ["z"] = 14, ["name"] = "wool:green"}, {["x"] = 2, ["y"] = 0, ["z"] = 1, ["name"] = "default:wood"}, {["x"] = 2, ["y"] = 0, ["z"] = 2, ["name"] = "default:wood"}, {["x"] = 2, ["y"] = 0, ["z"] = 13, ["name"] = "default:wood"}, {["x"] = 2, ["y"] = 0, ["z"] = 14, ["name"] = "default:wood"}, {["x"] = 2, ["y"] = 1, ["z"] = 1, ["name"] = "default:wood"}, {["x"] = 2, ["y"] = 1, ["z"] = 2, ["name"] = "default:wood"}, {["x"] = 2, ["y"] = 1, ["z"] = 13, ["name"] = "default:wood"}, {["x"] = 2, ["y"] = 1, ["z"] = 14, ["name"] = "default:wood"}, {["x"] = 2, ["y"] = 2, ["z"] = 1, ["name"] = "default:wood"}, {["x"] = 2, ["y"] = 2, ["z"] = 2, ["name"] = "default:wood"}, {["x"] = 2, ["y"] = 2, ["z"] = 13, ["name"] = "default:wood"}, {["x"] = 2, ["y"] = 2, ["z"] = 14, ["name"] = "default:wood"}, {["x"] = 2, ["y"] = 3, ["z"] = 1, ["name"] = "default:wood"}, {["x"] = 2, ["y"] = 3, ["z"] = 2, ["name"] = "default:wood"}, {["x"] = 2, ["y"] = 3, ["z"] = 13, ["name"] = "default:wood"}, {["x"] = 2, ["y"] = 3, ["z"] = 14, ["name"] = "default:wood"}, {["x"] = 2, ["y"] = 4, ["z"] = 1, ["name"] = "default:wood"}, {["x"] = 2, ["y"] = 4, ["z"] = 2, ["name"] = "default:wood"}, {["x"] = 2, ["y"] = 4, ["z"] = 13, ["name"] = "default:wood"}, {["x"] = 2, ["y"] = 4, ["z"] = 14, ["name"] = "default:wood"}, {["x"] = 2, ["y"] = 5, ["z"] = 1, ["name"] = "default:wood"}, {["x"] = 2, ["y"] = 5, ["z"] = 2, ["name"] = "default:wood"}, {["x"] = 2, ["y"] = 5, ["z"] = 13, ["name"] = "default:wood"}, {["x"] = 2, ["y"] = 5, ["z"] = 14, ["name"] = "default:wood"}, {["x"] = 2, ["y"] = 6, ["z"] = 1, ["name"] = "default:wood"}, {["x"] = 2, ["y"] = 6, ["z"] = 2, ["name"] = "default:wood"}, {["x"] = 2, ["y"] = 6, ["z"] = 13, ["name"] = "default:wood"}, {["x"] = 2, ["y"] = 6, ["z"] = 14, ["name"] = "default:wood"}, {["x"] = 2, ["y"] = 7, ["z"] = 1, ["name"] = "default:wood"}, {["x"] = 2, ["y"] = 7, ["z"] = 2, ["name"] = "default:wood"}, {["x"] = 2, ["y"] = 7, ["z"] = 13, ["name"] = "default:wood"}, {["x"] = 2, ["y"] = 7, ["z"] = 14, ["name"] = "default:wood"}, {["x"] = 2, ["y"] = 8, ["z"] = 1, ["name"] = "default:wood"}, {["x"] = 2, ["y"] = 8, ["z"] = 2, ["name"] = "default:wood"}, {["x"] = 2, ["y"] = 8, ["z"] = 13, ["name"] = "default:wood"}, {["x"] = 2, ["y"] = 8, ["z"] = 14, ["name"] = "default:wood"}, {["x"] = 2, ["y"] = 9, ["z"] = 0, ["name"] = "default:junglewood"}, {["x"] = 2, ["y"] = 9, ["z"] = 1, ["name"] = "default:wood"}, {["x"] = 2, ["y"] = 9, ["z"] = 2, ["name"] = "default:wood"}, {["x"] = 2, ["y"] = 9, ["z"] = 3, ["name"] = "default:junglewood"}, {["x"] = 2, ["y"] = 9, ["z"] = 4, ["name"] = "default:junglewood"}, {["x"] = 2, ["y"] = 9, ["z"] = 5, ["name"] = "default:junglewood"}, {["x"] = 2, ["y"] = 9, ["z"] = 6, ["name"] = "default:junglewood"}, {["x"] = 2, ["y"] = 9, ["z"] = 7, ["name"] = "default:junglewood"}, {["x"] = 2, ["y"] = 9, ["z"] = 8, ["name"] = "default:junglewood"}, {["x"] = 2, ["y"] = 9, ["z"] = 9, ["name"] = "default:junglewood"}, {["x"] = 2, ["y"] = 9, ["z"] = 10, ["name"] = "default:junglewood"}, {["x"] = 2, ["y"] = 9, ["z"] = 11, ["name"] = "default:junglewood"}, {["x"] = 2, ["y"] = 9, ["z"] = 12, ["name"] = "default:junglewood"}, {["x"] = 2, ["y"] = 9, ["z"] = 13, ["name"] = "default:wood"}, {["x"] = 2, ["y"] = 9, ["z"] = 14, ["name"] = "default:wood"}, {["x"] = 2, ["y"] = 9, ["z"] = 15, ["name"] = "default:junglewood"}, {["x"] = 2, ["y"] = 10, ["z"] = 0, ["name"] = "default:junglewood"}, {["x"] = 2, ["y"] = 10, ["z"] = 1, ["name"] = "default:junglewood"}, {["x"] = 2, ["y"] = 10, ["z"] = 2, ["name"] = "default:junglewood"}, {["x"] = 2, ["y"] = 10, ["z"] = 3, ["name"] = "default:junglewood"}, {["x"] = 2, ["y"] = 10, ["z"] = 4, ["name"] = "default:junglewood"}, {["x"] = 2, ["y"] = 10, ["z"] = 5, ["name"] = "default:junglewood"}, {["x"] = 2, ["y"] = 10, ["z"] = 6, ["name"] = "default:junglewood"}, {["x"] = 2, ["y"] = 10, ["z"] = 7, ["name"] = "default:junglewood"}, {["x"] = 2, ["y"] = 10, ["z"] = 8, ["name"] = "default:junglewood"}, {["x"] = 2, ["y"] = 10, ["z"] = 9, ["name"] = "default:junglewood"}, {["x"] = 2, ["y"] = 10, ["z"] = 10, ["name"] = "default:junglewood"}, {["x"] = 2, ["y"] = 10, ["z"] = 11, ["name"] = "default:junglewood"}, {["x"] = 2, ["y"] = 10, ["z"] = 12, ["name"] = "default:junglewood"}, {["x"] = 2, ["y"] = 10, ["z"] = 13, ["name"] = "default:junglewood"}, {["x"] = 2, ["y"] = 10, ["z"] = 14, ["name"] = "default:junglewood"}, {["x"] = 2, ["y"] = 10, ["z"] = 15, ["name"] = "default:junglewood"}, {["x"] = 2, ["y"] = 11, ["z"] = 7, ["name"] = "wool:green"}, {["x"] = 2, ["y"] = 11, ["z"] = 8, ["name"] = "wool:green"}, {["x"] = 2, ["y"] = 11, ["z"] = 9, ["name"] = "wool:green"}, {["x"] = 2, ["y"] = 11, ["z"] = 10, ["name"] = "wool:green"}, {["x"] = 2, ["y"] = 11, ["z"] = 11, ["name"] = "wool:green"}, {["x"] = 2, ["y"] = 11, ["z"] = 12, ["name"] = "wool:green"}, {["x"] = 2, ["y"] = 11, ["z"] = 13, ["name"] = "wool:green"}, {["x"] = 2, ["y"] = 11, ["z"] = 14, ["name"] = "wool:green"}, {["x"] = 3, ["y"] = 9, ["z"] = 0, ["name"] = "default:junglewood"}, {["x"] = 3, ["y"] = 9, ["z"] = 1, ["name"] = "default:junglewood"}, {["x"] = 3, ["y"] = 9, ["z"] = 2, ["name"] = "default:junglewood"}, {["x"] = 3, ["y"] = 9, ["z"] = 3, ["name"] = "default:junglewood"}, {["x"] = 3, ["y"] = 9, ["z"] = 4, ["name"] = "default:junglewood"}, {["x"] = 3, ["y"] = 9, ["z"] = 5, ["name"] = "default:junglewood"}, {["x"] = 3, ["y"] = 9, ["z"] = 6, ["name"] = "default:junglewood"}, {["x"] = 3, ["y"] = 9, ["z"] = 7, ["name"] = "default:junglewood"}, {["x"] = 3, ["y"] = 9, ["z"] = 8, ["name"] = "default:junglewood"}, {["x"] = 3, ["y"] = 9, ["z"] = 9, ["name"] = "default:junglewood"}, {["x"] = 3, ["y"] = 9, ["z"] = 10, ["name"] = "default:junglewood"}, {["x"] = 3, ["y"] = 9, ["z"] = 11, ["name"] = "default:junglewood"}, {["x"] = 3, ["y"] = 9, ["z"] = 12, ["name"] = "default:junglewood"}, {["x"] = 3, ["y"] = 9, ["z"] = 13, ["name"] = "default:junglewood"}, {["x"] = 3, ["y"] = 9, ["z"] = 14, ["name"] = "default:junglewood"}, {["x"] = 3, ["y"] = 9, ["z"] = 15, ["name"] = "default:junglewood"}, {["x"] = 3, ["y"] = 10, ["z"] = 0, ["name"] = "default:junglewood"}, {["x"] = 3, ["y"] = 10, ["z"] = 1, ["name"] = "default:junglewood"}, {["x"] = 3, ["y"] = 10, ["z"] = 2, ["name"] = "default:junglewood"}, {["x"] = 3, ["y"] = 10, ["z"] = 3, ["name"] = "default:junglewood"}, {["x"] = 3, ["y"] = 10, ["z"] = 4, ["name"] = "default:junglewood"}, {["x"] = 3, ["y"] = 10, ["z"] = 5, ["name"] = "default:junglewood"}, {["x"] = 3, ["y"] = 10, ["z"] = 6, ["name"] = "default:junglewood"}, {["x"] = 3, ["y"] = 10, ["z"] = 7, ["name"] = "default:junglewood"}, {["x"] = 3, ["y"] = 10, ["z"] = 8, ["name"] = "default:junglewood"}, {["x"] = 3, ["y"] = 10, ["z"] = 9, ["name"] = "default:junglewood"}, {["x"] = 3, ["y"] = 10, ["z"] = 10, ["name"] = "default:junglewood"}, {["x"] = 3, ["y"] = 10, ["z"] = 11, ["name"] = "default:junglewood"}, {["x"] = 3, ["y"] = 10, ["z"] = 12, ["name"] = "default:junglewood"}, {["x"] = 3, ["y"] = 10, ["z"] = 13, ["name"] = "default:junglewood"}, {["x"] = 3, ["y"] = 10, ["z"] = 14, ["name"] = "default:junglewood"}, {["x"] = 3, ["y"] = 10, ["z"] = 15, ["name"] = "default:junglewood"}, {["x"] = 3, ["y"] = 11, ["z"] = 7, ["name"] = "wool:green"}, {["x"] = 3, ["y"] = 11, ["z"] = 8, ["name"] = "wool:green"}, {["x"] = 3, ["y"] = 11, ["z"] = 9, ["name"] = "wool:green"}, {["x"] = 3, ["y"] = 11, ["z"] = 10, ["name"] = "wool:green"}, {["x"] = 3, ["y"] = 11, ["z"] = 11, ["name"] = "wool:green"}, {["x"] = 3, ["y"] = 11, ["z"] = 12, ["name"] = "wool:green"}, {["x"] = 3, ["y"] = 11, ["z"] = 13, ["name"] = "wool:green"}, {["x"] = 3, ["y"] = 11, ["z"] = 14, ["name"] = "wool:green"}, {["x"] = 4, ["y"] = 9, ["z"] = 0, ["name"] = "default:junglewood"}, {["x"] = 4, ["y"] = 9, ["z"] = 1, ["name"] = "default:junglewood"}, {["x"] = 4, ["y"] = 9, ["z"] = 2, ["name"] = "default:junglewood"}, {["x"] = 4, ["y"] = 9, ["z"] = 3, ["name"] = "default:junglewood"}, {["x"] = 4, ["y"] = 9, ["z"] = 4, ["name"] = "default:junglewood"}, {["x"] = 4, ["y"] = 9, ["z"] = 5, ["name"] = "default:junglewood"}, {["x"] = 4, ["y"] = 9, ["z"] = 6, ["name"] = "default:junglewood"}, {["x"] = 4, ["y"] = 9, ["z"] = 7, ["name"] = "default:junglewood"}, {["x"] = 4, ["y"] = 9, ["z"] = 8, ["name"] = "default:junglewood"}, {["x"] = 4, ["y"] = 9, ["z"] = 9, ["name"] = "default:junglewood"}, {["x"] = 4, ["y"] = 9, ["z"] = 10, ["name"] = "default:junglewood"}, {["x"] = 4, ["y"] = 9, ["z"] = 11, ["name"] = "default:junglewood"}, {["x"] = 4, ["y"] = 9, ["z"] = 12, ["name"] = "default:junglewood"}, {["x"] = 4, ["y"] = 9, ["z"] = 13, ["name"] = "default:junglewood"}, {["x"] = 4, ["y"] = 9, ["z"] = 14, ["name"] = "default:junglewood"}, {["x"] = 4, ["y"] = 9, ["z"] = 15, ["name"] = "default:junglewood"}, {["x"] = 4, ["y"] = 10, ["z"] = 0, ["name"] = "default:junglewood"}, {["x"] = 4, ["y"] = 10, ["z"] = 1, ["name"] = "default:junglewood"}, {["x"] = 4, ["y"] = 10, ["z"] = 2, ["name"] = "default:junglewood"}, {["x"] = 4, ["y"] = 10, ["z"] = 3, ["name"] = "default:junglewood"}, {["x"] = 4, ["y"] = 10, ["z"] = 4, ["name"] = "default:junglewood"}, {["x"] = 4, ["y"] = 10, ["z"] = 5, ["name"] = "default:junglewood"}, {["x"] = 4, ["y"] = 10, ["z"] = 6, ["name"] = "default:junglewood"}, {["x"] = 4, ["y"] = 10, ["z"] = 7, ["name"] = "default:junglewood"}, {["x"] = 4, ["y"] = 10, ["z"] = 8, ["name"] = "default:junglewood"}, {["x"] = 4, ["y"] = 10, ["z"] = 9, ["name"] = "default:junglewood"}, {["x"] = 4, ["y"] = 10, ["z"] = 10, ["name"] = "default:junglewood"}, {["x"] = 4, ["y"] = 10, ["z"] = 11, ["name"] = "default:junglewood"}, {["x"] = 4, ["y"] = 10, ["z"] = 12, ["name"] = "default:junglewood"}, {["x"] = 4, ["y"] = 10, ["z"] = 13, ["name"] = "default:junglewood"}, {["x"] = 4, ["y"] = 10, ["z"] = 14, ["name"] = "default:junglewood"}, {["x"] = 4, ["y"] = 10, ["z"] = 15, ["name"] = "default:junglewood"}, {["x"] = 4, ["y"] = 11, ["z"] = 7, ["name"] = "wool:green"}, {["x"] = 4, ["y"] = 11, ["z"] = 8, ["name"] = "wool:green"}, {["x"] = 4, ["y"] = 11, ["z"] = 9, ["name"] = "wool:green"}, {["x"] = 4, ["y"] = 11, ["z"] = 10, ["name"] = "wool:green"}, {["x"] = 4, ["y"] = 11, ["z"] = 11, ["name"] = "wool:green"}, {["x"] = 4, ["y"] = 11, ["z"] = 12, ["name"] = "wool:green"}, {["x"] = 4, ["y"] = 11, ["z"] = 13, ["name"] = "wool:green"}, {["x"] = 4, ["y"] = 11, ["z"] = 14, ["name"] = "wool:green"}, {["x"] = 5, ["y"] = 9, ["z"] = 0, ["name"] = "default:junglewood"}, {["x"] = 5, ["y"] = 9, ["z"] = 1, ["name"] = "default:junglewood"}, {["x"] = 5, ["y"] = 9, ["z"] = 2, ["name"] = "default:junglewood"}, {["x"] = 5, ["y"] = 9, ["z"] = 3, ["name"] = "default:junglewood"}, {["x"] = 5, ["y"] = 9, ["z"] = 4, ["name"] = "default:junglewood"}, {["x"] = 5, ["y"] = 9, ["z"] = 5, ["name"] = "default:junglewood"}, {["x"] = 5, ["y"] = 9, ["z"] = 6, ["name"] = "default:junglewood"}, {["x"] = 5, ["y"] = 9, ["z"] = 7, ["name"] = "default:junglewood"}, {["x"] = 5, ["y"] = 9, ["z"] = 8, ["name"] = "default:junglewood"}, {["x"] = 5, ["y"] = 9, ["z"] = 9, ["name"] = "default:junglewood"}, {["x"] = 5, ["y"] = 9, ["z"] = 10, ["name"] = "default:junglewood"}, {["x"] = 5, ["y"] = 9, ["z"] = 11, ["name"] = "default:junglewood"}, {["x"] = 5, ["y"] = 9, ["z"] = 12, ["name"] = "default:junglewood"}, {["x"] = 5, ["y"] = 9, ["z"] = 13, ["name"] = "default:junglewood"}, {["x"] = 5, ["y"] = 9, ["z"] = 14, ["name"] = "default:junglewood"}, {["x"] = 5, ["y"] = 9, ["z"] = 15, ["name"] = "default:junglewood"}, {["x"] = 5, ["y"] = 10, ["z"] = 0, ["name"] = "default:junglewood"}, {["x"] = 5, ["y"] = 10, ["z"] = 1, ["name"] = "default:junglewood"}, {["x"] = 5, ["y"] = 10, ["z"] = 2, ["name"] = "default:junglewood"}, {["x"] = 5, ["y"] = 10, ["z"] = 3, ["name"] = "default:junglewood"}, {["x"] = 5, ["y"] = 10, ["z"] = 4, ["name"] = "default:junglewood"}, {["x"] = 5, ["y"] = 10, ["z"] = 5, ["name"] = "default:junglewood"}, {["x"] = 5, ["y"] = 10, ["z"] = 6, ["name"] = "default:junglewood"}, {["x"] = 5, ["y"] = 10, ["z"] = 7, ["name"] = "default:junglewood"}, {["x"] = 5, ["y"] = 10, ["z"] = 8, ["name"] = "default:junglewood"}, {["x"] = 5, ["y"] = 10, ["z"] = 9, ["name"] = "default:junglewood"}, {["x"] = 5, ["y"] = 10, ["z"] = 10, ["name"] = "default:junglewood"}, {["x"] = 5, ["y"] = 10, ["z"] = 11, ["name"] = "default:junglewood"}, {["x"] = 5, ["y"] = 10, ["z"] = 12, ["name"] = "default:junglewood"}, {["x"] = 5, ["y"] = 10, ["z"] = 13, ["name"] = "default:junglewood"}, {["x"] = 5, ["y"] = 10, ["z"] = 14, ["name"] = "default:junglewood"}, {["x"] = 5, ["y"] = 10, ["z"] = 15, ["name"] = "default:junglewood"}, {["x"] = 5, ["y"] = 11, ["z"] = 7, ["name"] = "wool:green"}, {["x"] = 5, ["y"] = 11, ["z"] = 8, ["name"] = "wool:green"}, {["x"] = 5, ["y"] = 11, ["z"] = 9, ["name"] = "wool:green"}, {["x"] = 5, ["y"] = 11, ["z"] = 10, ["name"] = "wool:green"}, {["x"] = 5, ["y"] = 11, ["z"] = 11, ["name"] = "wool:green"}, {["x"] = 5, ["y"] = 11, ["z"] = 12, ["name"] = "wool:green"}, {["x"] = 5, ["y"] = 11, ["z"] = 13, ["name"] = "wool:green"}, {["x"] = 5, ["y"] = 11, ["z"] = 14, ["name"] = "wool:green"}, {["x"] = 6, ["y"] = 9, ["z"] = 0, ["name"] = "default:junglewood"}, {["x"] = 6, ["y"] = 9, ["z"] = 1, ["name"] = "default:junglewood"}, {["x"] = 6, ["y"] = 9, ["z"] = 2, ["name"] = "default:junglewood"}, {["x"] = 6, ["y"] = 9, ["z"] = 3, ["name"] = "default:junglewood"}, {["x"] = 6, ["y"] = 9, ["z"] = 4, ["name"] = "default:junglewood"}, {["x"] = 6, ["y"] = 9, ["z"] = 5, ["name"] = "default:junglewood"}, {["x"] = 6, ["y"] = 9, ["z"] = 6, ["name"] = "default:junglewood"}, {["x"] = 6, ["y"] = 9, ["z"] = 7, ["name"] = "default:junglewood"}, {["x"] = 6, ["y"] = 9, ["z"] = 8, ["name"] = "default:junglewood"}, {["x"] = 6, ["y"] = 9, ["z"] = 9, ["name"] = "default:junglewood"}, {["x"] = 6, ["y"] = 9, ["z"] = 10, ["name"] = "default:junglewood"}, {["x"] = 6, ["y"] = 9, ["z"] = 11, ["name"] = "default:junglewood"}, {["x"] = 6, ["y"] = 9, ["z"] = 12, ["name"] = "default:junglewood"}, {["x"] = 6, ["y"] = 9, ["z"] = 13, ["name"] = "default:junglewood"}, {["x"] = 6, ["y"] = 9, ["z"] = 14, ["name"] = "default:junglewood"}, {["x"] = 6, ["y"] = 9, ["z"] = 15, ["name"] = "default:junglewood"}, {["x"] = 6, ["y"] = 10, ["z"] = 0, ["name"] = "default:junglewood"}, {["x"] = 6, ["y"] = 10, ["z"] = 1, ["name"] = "default:junglewood"}, {["x"] = 6, ["y"] = 10, ["z"] = 2, ["name"] = "default:junglewood"}, {["x"] = 6, ["y"] = 10, ["z"] = 3, ["name"] = "default:junglewood"}, {["x"] = 6, ["y"] = 10, ["z"] = 4, ["name"] = "default:junglewood"}, {["x"] = 6, ["y"] = 10, ["z"] = 5, ["name"] = "default:junglewood"}, {["x"] = 6, ["y"] = 10, ["z"] = 6, ["name"] = "default:junglewood"}, {["x"] = 6, ["y"] = 10, ["z"] = 7, ["name"] = "default:junglewood"}, {["x"] = 6, ["y"] = 10, ["z"] = 8, ["name"] = "default:junglewood"}, {["x"] = 6, ["y"] = 10, ["z"] = 9, ["name"] = "default:junglewood"}, {["x"] = 6, ["y"] = 10, ["z"] = 10, ["name"] = "default:junglewood"}, {["x"] = 6, ["y"] = 10, ["z"] = 11, ["name"] = "default:junglewood"}, {["x"] = 6, ["y"] = 10, ["z"] = 12, ["name"] = "default:junglewood"}, {["x"] = 6, ["y"] = 10, ["z"] = 13, ["name"] = "default:junglewood"}, {["x"] = 6, ["y"] = 10, ["z"] = 14, ["name"] = "default:junglewood"}, {["x"] = 6, ["y"] = 10, ["z"] = 15, ["name"] = "default:junglewood"}, {["x"] = 6, ["y"] = 11, ["z"] = 7, ["name"] = "wool:green"}, {["x"] = 6, ["y"] = 11, ["z"] = 8, ["name"] = "wool:green"}, {["x"] = 6, ["y"] = 11, ["z"] = 9, ["name"] = "wool:green"}, {["x"] = 6, ["y"] = 11, ["z"] = 10, ["name"] = "wool:green"}, {["x"] = 6, ["y"] = 11, ["z"] = 11, ["name"] = "wool:green"}, {["x"] = 6, ["y"] = 11, ["z"] = 12, ["name"] = "wool:green"}, {["x"] = 6, ["y"] = 11, ["z"] = 13, ["name"] = "wool:green"}, {["x"] = 6, ["y"] = 11, ["z"] = 14, ["name"] = "wool:green"}, {["x"] = 7, ["y"] = 9, ["z"] = 0, ["name"] = "default:junglewood"}, {["x"] = 7, ["y"] = 9, ["z"] = 1, ["name"] = "default:junglewood"}, {["x"] = 7, ["y"] = 9, ["z"] = 2, ["name"] = "default:junglewood"}, {["x"] = 7, ["y"] = 9, ["z"] = 3, ["name"] = "default:junglewood"}, {["x"] = 7, ["y"] = 9, ["z"] = 4, ["name"] = "default:junglewood"}, {["x"] = 7, ["y"] = 9, ["z"] = 5, ["name"] = "default:junglewood"}, {["x"] = 7, ["y"] = 9, ["z"] = 6, ["name"] = "default:junglewood"}, {["x"] = 7, ["y"] = 9, ["z"] = 7, ["name"] = "default:junglewood"}, {["x"] = 7, ["y"] = 9, ["z"] = 8, ["name"] = "default:junglewood"}, {["x"] = 7, ["y"] = 9, ["z"] = 9, ["name"] = "default:junglewood"}, {["x"] = 7, ["y"] = 9, ["z"] = 10, ["name"] = "default:junglewood"}, {["x"] = 7, ["y"] = 9, ["z"] = 11, ["name"] = "default:junglewood"}, {["x"] = 7, ["y"] = 9, ["z"] = 12, ["name"] = "default:junglewood"}, {["x"] = 7, ["y"] = 9, ["z"] = 13, ["name"] = "default:junglewood"}, {["x"] = 7, ["y"] = 9, ["z"] = 14, ["name"] = "default:junglewood"}, {["x"] = 7, ["y"] = 9, ["z"] = 15, ["name"] = "default:junglewood"}, {["x"] = 7, ["y"] = 10, ["z"] = 0, ["name"] = "default:junglewood"}, {["x"] = 7, ["y"] = 10, ["z"] = 1, ["name"] = "default:junglewood"}, {["x"] = 7, ["y"] = 10, ["z"] = 2, ["name"] = "default:junglewood"}, {["x"] = 7, ["y"] = 10, ["z"] = 3, ["name"] = "default:junglewood"}, {["x"] = 7, ["y"] = 10, ["z"] = 4, ["name"] = "default:junglewood"}, {["x"] = 7, ["y"] = 10, ["z"] = 5, ["name"] = "default:junglewood"}, {["x"] = 7, ["y"] = 10, ["z"] = 6, ["name"] = "default:junglewood"}, {["x"] = 7, ["y"] = 10, ["z"] = 7, ["name"] = "default:junglewood"}, {["x"] = 7, ["y"] = 10, ["z"] = 8, ["name"] = "default:junglewood"}, {["x"] = 7, ["y"] = 10, ["z"] = 9, ["name"] = "default:junglewood"}, {["x"] = 7, ["y"] = 10, ["z"] = 10, ["name"] = "default:junglewood"}, {["x"] = 7, ["y"] = 10, ["z"] = 11, ["name"] = "default:junglewood"}, {["x"] = 7, ["y"] = 10, ["z"] = 12, ["name"] = "default:junglewood"}, {["x"] = 7, ["y"] = 10, ["z"] = 13, ["name"] = "default:junglewood"}, {["x"] = 7, ["y"] = 10, ["z"] = 14, ["name"] = "default:junglewood"}, {["x"] = 7, ["y"] = 10, ["z"] = 15, ["name"] = "default:junglewood"}, {["x"] = 7, ["y"] = 11, ["z"] = 7, ["name"] = "wool:green"}, {["x"] = 7, ["y"] = 11, ["z"] = 8, ["name"] = "wool:green"}, {["x"] = 7, ["y"] = 11, ["z"] = 9, ["name"] = "wool:green"}, {["x"] = 7, ["y"] = 11, ["z"] = 10, ["name"] = "wool:green"}, {["x"] = 7, ["y"] = 11, ["z"] = 11, ["name"] = "wool:green"}, {["x"] = 7, ["y"] = 11, ["z"] = 12, ["name"] = "wool:green"}, {["x"] = 7, ["y"] = 11, ["z"] = 13, ["name"] = "wool:green"}, {["x"] = 7, ["y"] = 11, ["z"] = 14, ["name"] = "wool:green"}, {["x"] = 8, ["y"] = 9, ["z"] = 0, ["name"] = "default:junglewood"}, {["x"] = 8, ["y"] = 9, ["z"] = 1, ["name"] = "default:junglewood"}, {["x"] = 8, ["y"] = 9, ["z"] = 2, ["name"] = "default:junglewood"}, {["x"] = 8, ["y"] = 9, ["z"] = 3, ["name"] = "default:junglewood"}, {["x"] = 8, ["y"] = 9, ["z"] = 4, ["name"] = "default:junglewood"}, {["x"] = 8, ["y"] = 9, ["z"] = 5, ["name"] = "default:junglewood"}, {["x"] = 8, ["y"] = 9, ["z"] = 6, ["name"] = "default:junglewood"}, {["x"] = 8, ["y"] = 9, ["z"] = 7, ["name"] = "default:junglewood"}, {["x"] = 8, ["y"] = 9, ["z"] = 8, ["name"] = "default:junglewood"}, {["x"] = 8, ["y"] = 9, ["z"] = 9, ["name"] = "default:junglewood"}, {["x"] = 8, ["y"] = 9, ["z"] = 10, ["name"] = "default:junglewood"}, {["x"] = 8, ["y"] = 9, ["z"] = 11, ["name"] = "default:junglewood"}, {["x"] = 8, ["y"] = 9, ["z"] = 12, ["name"] = "default:junglewood"}, {["x"] = 8, ["y"] = 9, ["z"] = 13, ["name"] = "default:junglewood"}, {["x"] = 8, ["y"] = 9, ["z"] = 14, ["name"] = "default:junglewood"}, {["x"] = 8, ["y"] = 9, ["z"] = 15, ["name"] = "default:junglewood"}, {["x"] = 8, ["y"] = 10, ["z"] = 0, ["name"] = "default:junglewood"}, {["x"] = 8, ["y"] = 10, ["z"] = 1, ["name"] = "default:junglewood"}, {["x"] = 8, ["y"] = 10, ["z"] = 2, ["name"] = "default:junglewood"}, {["x"] = 8, ["y"] = 10, ["z"] = 3, ["name"] = "default:junglewood"}, {["x"] = 8, ["y"] = 10, ["z"] = 4, ["name"] = "default:junglewood"}, {["x"] = 8, ["y"] = 10, ["z"] = 5, ["name"] = "default:junglewood"}, {["x"] = 8, ["y"] = 10, ["z"] = 6, ["name"] = "default:junglewood"}, {["x"] = 8, ["y"] = 10, ["z"] = 7, ["name"] = "default:junglewood"}, {["x"] = 8, ["y"] = 10, ["z"] = 8, ["name"] = "default:junglewood"}, {["x"] = 8, ["y"] = 10, ["z"] = 9, ["name"] = "default:junglewood"}, {["x"] = 8, ["y"] = 10, ["z"] = 10, ["name"] = "default:junglewood"}, {["x"] = 8, ["y"] = 10, ["z"] = 11, ["name"] = "default:junglewood"}, {["x"] = 8, ["y"] = 10, ["z"] = 12, ["name"] = "default:junglewood"}, {["x"] = 8, ["y"] = 10, ["z"] = 13, ["name"] = "default:junglewood"}, {["x"] = 8, ["y"] = 10, ["z"] = 14, ["name"] = "default:junglewood"}, {["x"] = 8, ["y"] = 10, ["z"] = 15, ["name"] = "default:junglewood"}, {["x"] = 8, ["y"] = 11, ["z"] = 7, ["name"] = "wool:green"}, {["x"] = 8, ["y"] = 11, ["z"] = 8, ["name"] = "wool:green"}, {["x"] = 8, ["y"] = 11, ["z"] = 9, ["name"] = "wool:green"}, {["x"] = 8, ["y"] = 11, ["z"] = 10, ["name"] = "wool:green"}, {["x"] = 8, ["y"] = 11, ["z"] = 11, ["name"] = "wool:green"}, {["x"] = 8, ["y"] = 11, ["z"] = 12, ["name"] = "wool:green"}, {["x"] = 8, ["y"] = 11, ["z"] = 13, ["name"] = "wool:green"}, {["x"] = 8, ["y"] = 11, ["z"] = 14, ["name"] = "wool:green"}, {["x"] = 9, ["y"] = 9, ["z"] = 0, ["name"] = "default:junglewood"}, {["x"] = 9, ["y"] = 9, ["z"] = 1, ["name"] = "default:junglewood"}, {["x"] = 9, ["y"] = 9, ["z"] = 2, ["name"] = "default:junglewood"}, {["x"] = 9, ["y"] = 9, ["z"] = 3, ["name"] = "default:junglewood"}, {["x"] = 9, ["y"] = 9, ["z"] = 4, ["name"] = "default:junglewood"}, {["x"] = 9, ["y"] = 9, ["z"] = 5, ["name"] = "default:junglewood"}, {["x"] = 9, ["y"] = 9, ["z"] = 6, ["name"] = "default:junglewood"}, {["x"] = 9, ["y"] = 9, ["z"] = 7, ["name"] = "default:junglewood"}, {["x"] = 9, ["y"] = 9, ["z"] = 8, ["name"] = "default:junglewood"}, {["x"] = 9, ["y"] = 9, ["z"] = 9, ["name"] = "default:junglewood"}, {["x"] = 9, ["y"] = 9, ["z"] = 10, ["name"] = "default:junglewood"}, {["x"] = 9, ["y"] = 9, ["z"] = 11, ["name"] = "default:junglewood"}, {["x"] = 9, ["y"] = 9, ["z"] = 12, ["name"] = "default:junglewood"}, {["x"] = 9, ["y"] = 9, ["z"] = 13, ["name"] = "default:junglewood"}, {["x"] = 9, ["y"] = 9, ["z"] = 14, ["name"] = "default:junglewood"}, {["x"] = 9, ["y"] = 9, ["z"] = 15, ["name"] = "default:junglewood"}, {["x"] = 9, ["y"] = 10, ["z"] = 0, ["name"] = "default:junglewood"}, {["x"] = 9, ["y"] = 10, ["z"] = 1, ["name"] = "default:junglewood"}, {["x"] = 9, ["y"] = 10, ["z"] = 2, ["name"] = "default:junglewood"}, {["x"] = 9, ["y"] = 10, ["z"] = 3, ["name"] = "default:junglewood"}, {["x"] = 9, ["y"] = 10, ["z"] = 4, ["name"] = "default:junglewood"}, {["x"] = 9, ["y"] = 10, ["z"] = 5, ["name"] = "default:junglewood"}, {["x"] = 9, ["y"] = 10, ["z"] = 6, ["name"] = "default:junglewood"}, {["x"] = 9, ["y"] = 10, ["z"] = 7, ["name"] = "default:junglewood"}, {["x"] = 9, ["y"] = 10, ["z"] = 8, ["name"] = "default:junglewood"}, {["x"] = 9, ["y"] = 10, ["z"] = 9, ["name"] = "default:junglewood"}, {["x"] = 9, ["y"] = 10, ["z"] = 10, ["name"] = "default:junglewood"}, {["x"] = 9, ["y"] = 10, ["z"] = 11, ["name"] = "default:junglewood"}, {["x"] = 9, ["y"] = 10, ["z"] = 12, ["name"] = "default:junglewood"}, {["x"] = 9, ["y"] = 10, ["z"] = 13, ["name"] = "default:junglewood"}, {["x"] = 9, ["y"] = 10, ["z"] = 14, ["name"] = "default:junglewood"}, {["x"] = 9, ["y"] = 10, ["z"] = 15, ["name"] = "default:junglewood"}, {["x"] = 10, ["y"] = 9, ["z"] = 0, ["name"] = "default:junglewood"}, {["x"] = 10, ["y"] = 9, ["z"] = 1, ["name"] = "default:junglewood"}, {["x"] = 10, ["y"] = 9, ["z"] = 2, ["name"] = "default:junglewood"}, {["x"] = 10, ["y"] = 9, ["z"] = 3, ["name"] = "default:junglewood"}, {["x"] = 10, ["y"] = 9, ["z"] = 4, ["name"] = "default:junglewood"}, {["x"] = 10, ["y"] = 9, ["z"] = 5, ["name"] = "default:junglewood"}, {["x"] = 10, ["y"] = 9, ["z"] = 6, ["name"] = "default:junglewood"}, {["x"] = 10, ["y"] = 9, ["z"] = 7, ["name"] = "default:junglewood"}, {["x"] = 10, ["y"] = 9, ["z"] = 8, ["name"] = "default:junglewood"}, {["x"] = 10, ["y"] = 9, ["z"] = 9, ["name"] = "default:junglewood"}, {["x"] = 10, ["y"] = 9, ["z"] = 10, ["name"] = "default:junglewood"}, {["x"] = 10, ["y"] = 9, ["z"] = 11, ["name"] = "default:junglewood"}, {["x"] = 10, ["y"] = 9, ["z"] = 12, ["name"] = "default:junglewood"}, {["x"] = 10, ["y"] = 9, ["z"] = 13, ["name"] = "default:junglewood"}, {["x"] = 10, ["y"] = 9, ["z"] = 14, ["name"] = "default:junglewood"}, {["x"] = 10, ["y"] = 9, ["z"] = 15, ["name"] = "default:junglewood"}, {["x"] = 10, ["y"] = 10, ["z"] = 0, ["name"] = "default:junglewood"}, {["x"] = 10, ["y"] = 10, ["z"] = 1, ["name"] = "default:junglewood"}, {["x"] = 10, ["y"] = 10, ["z"] = 2, ["name"] = "default:junglewood"}, {["x"] = 10, ["y"] = 10, ["z"] = 3, ["name"] = "default:junglewood"}, {["x"] = 10, ["y"] = 10, ["z"] = 4, ["name"] = "default:junglewood"}, {["x"] = 10, ["y"] = 10, ["z"] = 5, ["name"] = "default:junglewood"}, {["x"] = 10, ["y"] = 10, ["z"] = 6, ["name"] = "default:junglewood"}, {["x"] = 10, ["y"] = 10, ["z"] = 7, ["name"] = "default:junglewood"}, {["x"] = 10, ["y"] = 10, ["z"] = 8, ["name"] = "default:junglewood"}, {["x"] = 10, ["y"] = 10, ["z"] = 9, ["name"] = "default:junglewood"}, {["x"] = 10, ["y"] = 10, ["z"] = 10, ["name"] = "default:junglewood"}, {["x"] = 10, ["y"] = 10, ["z"] = 11, ["name"] = "default:junglewood"}, {["x"] = 10, ["y"] = 10, ["z"] = 12, ["name"] = "default:junglewood"}, {["x"] = 10, ["y"] = 10, ["z"] = 13, ["name"] = "default:junglewood"}, {["x"] = 10, ["y"] = 10, ["z"] = 14, ["name"] = "default:junglewood"}, {["x"] = 10, ["y"] = 10, ["z"] = 15, ["name"] = "default:junglewood"}, {["x"] = 11, ["y"] = 9, ["z"] = 0, ["name"] = "default:junglewood"}, {["x"] = 11, ["y"] = 9, ["z"] = 1, ["name"] = "default:junglewood"}, {["x"] = 11, ["y"] = 9, ["z"] = 2, ["name"] = "default:junglewood"}, {["x"] = 11, ["y"] = 9, ["z"] = 3, ["name"] = "default:junglewood"}, {["x"] = 11, ["y"] = 9, ["z"] = 4, ["name"] = "default:junglewood"}, {["x"] = 11, ["y"] = 9, ["z"] = 5, ["name"] = "default:junglewood"}, {["x"] = 11, ["y"] = 9, ["z"] = 6, ["name"] = "default:junglewood"}, {["x"] = 11, ["y"] = 9, ["z"] = 7, ["name"] = "default:junglewood"}, {["x"] = 11, ["y"] = 9, ["z"] = 8, ["name"] = "default:junglewood"}, {["x"] = 11, ["y"] = 9, ["z"] = 9, ["name"] = "default:junglewood"}, {["x"] = 11, ["y"] = 9, ["z"] = 10, ["name"] = "default:junglewood"}, {["x"] = 11, ["y"] = 9, ["z"] = 11, ["name"] = "default:junglewood"}, {["x"] = 11, ["y"] = 9, ["z"] = 12, ["name"] = "default:junglewood"}, {["x"] = 11, ["y"] = 9, ["z"] = 13, ["name"] = "default:junglewood"}, {["x"] = 11, ["y"] = 9, ["z"] = 14, ["name"] = "default:junglewood"}, {["x"] = 11, ["y"] = 9, ["z"] = 15, ["name"] = "default:junglewood"}, {["x"] = 11, ["y"] = 10, ["z"] = 0, ["name"] = "default:junglewood"}, {["x"] = 11, ["y"] = 10, ["z"] = 1, ["name"] = "default:junglewood"}, {["x"] = 11, ["y"] = 10, ["z"] = 2, ["name"] = "default:junglewood"}, {["x"] = 11, ["y"] = 10, ["z"] = 3, ["name"] = "default:junglewood"}, {["x"] = 11, ["y"] = 10, ["z"] = 4, ["name"] = "default:junglewood"}, {["x"] = 11, ["y"] = 10, ["z"] = 5, ["name"] = "default:junglewood"}, {["x"] = 11, ["y"] = 10, ["z"] = 6, ["name"] = "default:junglewood"}, {["x"] = 11, ["y"] = 10, ["z"] = 7, ["name"] = "default:junglewood"}, {["x"] = 11, ["y"] = 10, ["z"] = 8, ["name"] = "default:junglewood"}, {["x"] = 11, ["y"] = 10, ["z"] = 9, ["name"] = "default:junglewood"}, {["x"] = 11, ["y"] = 10, ["z"] = 10, ["name"] = "default:junglewood"}, {["x"] = 11, ["y"] = 10, ["z"] = 11, ["name"] = "default:junglewood"}, {["x"] = 11, ["y"] = 10, ["z"] = 12, ["name"] = "default:junglewood"}, {["x"] = 11, ["y"] = 10, ["z"] = 13, ["name"] = "default:junglewood"}, {["x"] = 11, ["y"] = 10, ["z"] = 14, ["name"] = "default:junglewood"}, {["x"] = 11, ["y"] = 10, ["z"] = 15, ["name"] = "default:junglewood"}, {["x"] = 11, ["y"] = 11, ["z"] = 1, ["name"] = "wool:white"}, {["x"] = 11, ["y"] = 11, ["z"] = 2, ["name"] = "wool:white"}, {["x"] = 11, ["y"] = 11, ["z"] = 3, ["name"] = "wool:white"}, {["x"] = 11, ["y"] = 11, ["z"] = 4, ["name"] = "wool:white"}, {["x"] = 11, ["y"] = 11, ["z"] = 5, ["name"] = "wool:white"}, {["x"] = 11, ["y"] = 12, ["z"] = 1, ["name"] = "wool:grey"}, {["x"] = 11, ["y"] = 12, ["z"] = 2, ["name"] = "wool:grey"}, {["x"] = 11, ["y"] = 12, ["z"] = 3, ["name"] = "wool:grey"}, {["x"] = 11, ["y"] = 12, ["z"] = 4, ["name"] = "wool:grey"}, {["x"] = 11, ["y"] = 12, ["z"] = 5, ["name"] = "wool:grey"}, {["x"] = 11, ["y"] = 13, ["z"] = 1, ["name"] = "wool:white"}, {["x"] = 11, ["y"] = 13, ["z"] = 2, ["name"] = "wool:white"}, {["x"] = 11, ["y"] = 13, ["z"] = 3, ["name"] = "wool:white"}, {["x"] = 11, ["y"] = 13, ["z"] = 4, ["name"] = "wool:white"}, {["x"] = 11, ["y"] = 13, ["z"] = 5, ["name"] = "wool:white"}, {["x"] = 11, ["y"] = 14, ["z"] = 1, ["name"] = "wool:grey"}, {["x"] = 11, ["y"] = 14, ["z"] = 2, ["name"] = "wool:grey"}, {["x"] = 11, ["y"] = 14, ["z"] = 3, ["name"] = "wool:grey"}, {["x"] = 11, ["y"] = 14, ["z"] = 4, ["name"] = "wool:grey"}, {["x"] = 11, ["y"] = 14, ["z"] = 5, ["name"] = "wool:grey"}, {["x"] = 11, ["y"] = 15, ["z"] = 1, ["name"] = "wool:white"}, {["x"] = 11, ["y"] = 15, ["z"] = 2, ["name"] = "wool:white"}, {["x"] = 11, ["y"] = 15, ["z"] = 3, ["name"] = "wool:white"}, {["x"] = 11, ["y"] = 15, ["z"] = 4, ["name"] = "wool:white"}, {["x"] = 11, ["y"] = 15, ["z"] = 5, ["name"] = "wool:white"}, {["x"] = 12, ["y"] = 9, ["z"] = 0, ["name"] = "default:junglewood"}, {["x"] = 12, ["y"] = 9, ["z"] = 1, ["name"] = "default:junglewood"}, {["x"] = 12, ["y"] = 9, ["z"] = 2, ["name"] = "default:junglewood"}, {["x"] = 12, ["y"] = 9, ["z"] = 3, ["name"] = "default:junglewood"}, {["x"] = 12, ["y"] = 9, ["z"] = 4, ["name"] = "default:junglewood"}, {["x"] = 12, ["y"] = 9, ["z"] = 5, ["name"] = "default:junglewood"}, {["x"] = 12, ["y"] = 9, ["z"] = 6, ["name"] = "default:junglewood"}, {["x"] = 12, ["y"] = 9, ["z"] = 7, ["name"] = "default:junglewood"}, {["x"] = 12, ["y"] = 9, ["z"] = 8, ["name"] = "default:junglewood"}, {["x"] = 12, ["y"] = 9, ["z"] = 9, ["name"] = "default:junglewood"}, {["x"] = 12, ["y"] = 9, ["z"] = 10, ["name"] = "default:junglewood"}, {["x"] = 12, ["y"] = 9, ["z"] = 11, ["name"] = "default:junglewood"}, {["x"] = 12, ["y"] = 9, ["z"] = 12, ["name"] = "default:junglewood"}, {["x"] = 12, ["y"] = 9, ["z"] = 13, ["name"] = "default:junglewood"}, {["x"] = 12, ["y"] = 9, ["z"] = 14, ["name"] = "default:junglewood"}, {["x"] = 12, ["y"] = 9, ["z"] = 15, ["name"] = "default:junglewood"}, {["x"] = 12, ["y"] = 10, ["z"] = 0, ["name"] = "default:junglewood"}, {["x"] = 12, ["y"] = 10, ["z"] = 1, ["name"] = "default:junglewood"}, {["x"] = 12, ["y"] = 10, ["z"] = 2, ["name"] = "default:junglewood"}, {["x"] = 12, ["y"] = 10, ["z"] = 3, ["name"] = "default:junglewood"}, {["x"] = 12, ["y"] = 10, ["z"] = 4, ["name"] = "default:junglewood"}, {["x"] = 12, ["y"] = 10, ["z"] = 5, ["name"] = "default:junglewood"}, {["x"] = 12, ["y"] = 10, ["z"] = 6, ["name"] = "default:junglewood"}, {["x"] = 12, ["y"] = 10, ["z"] = 7, ["name"] = "default:junglewood"}, {["x"] = 12, ["y"] = 10, ["z"] = 8, ["name"] = "default:junglewood"}, {["x"] = 12, ["y"] = 10, ["z"] = 9, ["name"] = "default:junglewood"}, {["x"] = 12, ["y"] = 10, ["z"] = 10, ["name"] = "default:junglewood"}, {["x"] = 12, ["y"] = 10, ["z"] = 11, ["name"] = "default:junglewood"}, {["x"] = 12, ["y"] = 10, ["z"] = 12, ["name"] = "default:junglewood"}, {["x"] = 12, ["y"] = 10, ["z"] = 13, ["name"] = "default:junglewood"}, {["x"] = 12, ["y"] = 10, ["z"] = 14, ["name"] = "default:junglewood"}, {["x"] = 12, ["y"] = 10, ["z"] = 15, ["name"] = "default:junglewood"}, {["x"] = 12, ["y"] = 11, ["z"] = 1, ["name"] = "wool:white"}, {["x"] = 12, ["y"] = 11, ["z"] = 2, ["name"] = "wool:white"}, {["x"] = 12, ["y"] = 11, ["z"] = 3, ["name"] = "wool:white"}, {["x"] = 12, ["y"] = 11, ["z"] = 4, ["name"] = "wool:white"}, {["x"] = 12, ["y"] = 11, ["z"] = 5, ["name"] = "wool:white"}, {["x"] = 12, ["y"] = 12, ["z"] = 1, ["name"] = "wool:grey"}, {["x"] = 12, ["y"] = 12, ["z"] = 2, ["name"] = "wool:grey"}, {["x"] = 12, ["y"] = 12, ["z"] = 3, ["name"] = "wool:grey"}, {["x"] = 12, ["y"] = 12, ["z"] = 4, ["name"] = "wool:grey"}, {["x"] = 12, ["y"] = 12, ["z"] = 5, ["name"] = "wool:grey"}, {["x"] = 12, ["y"] = 13, ["z"] = 1, ["name"] = "wool:white"}, {["x"] = 12, ["y"] = 13, ["z"] = 2, ["name"] = "wool:white"}, {["x"] = 12, ["y"] = 13, ["z"] = 3, ["name"] = "wool:white"}, {["x"] = 12, ["y"] = 13, ["z"] = 4, ["name"] = "wool:white"}, {["x"] = 12, ["y"] = 13, ["z"] = 5, ["name"] = "wool:white"}, {["x"] = 12, ["y"] = 14, ["z"] = 1, ["name"] = "wool:grey"}, {["x"] = 12, ["y"] = 14, ["z"] = 2, ["name"] = "wool:grey"}, {["x"] = 12, ["y"] = 14, ["z"] = 3, ["name"] = "wool:grey"}, {["x"] = 12, ["y"] = 14, ["z"] = 4, ["name"] = "wool:grey"}, {["x"] = 12, ["y"] = 14, ["z"] = 5, ["name"] = "wool:grey"}, {["x"] = 12, ["y"] = 15, ["z"] = 1, ["name"] = "wool:white"}, {["x"] = 12, ["y"] = 15, ["z"] = 2, ["name"] = "wool:white"}, {["x"] = 12, ["y"] = 15, ["z"] = 3, ["name"] = "wool:white"}, {["x"] = 12, ["y"] = 15, ["z"] = 4, ["name"] = "wool:white"}, {["x"] = 12, ["y"] = 15, ["z"] = 5, ["name"] = "wool:white"}, {["x"] = 13, ["y"] = 0, ["z"] = 1, ["name"] = "default:wood"}, {["x"] = 13, ["y"] = 0, ["z"] = 2, ["name"] = "default:wood"}, {["x"] = 13, ["y"] = 0, ["z"] = 13, ["name"] = "default:wood"}, {["x"] = 13, ["y"] = 0, ["z"] = 14, ["name"] = "default:wood"}, {["x"] = 13, ["y"] = 1, ["z"] = 1, ["name"] = "default:wood"}, {["x"] = 13, ["y"] = 1, ["z"] = 2, ["name"] = "default:wood"}, {["x"] = 13, ["y"] = 1, ["z"] = 13, ["name"] = "default:wood"}, {["x"] = 13, ["y"] = 1, ["z"] = 14, ["name"] = "default:wood"}, {["x"] = 13, ["y"] = 2, ["z"] = 1, ["name"] = "default:wood"}, {["x"] = 13, ["y"] = 2, ["z"] = 2, ["name"] = "default:wood"}, {["x"] = 13, ["y"] = 2, ["z"] = 13, ["name"] = "default:wood"}, {["x"] = 13, ["y"] = 2, ["z"] = 14, ["name"] = "default:wood"}, {["x"] = 13, ["y"] = 3, ["z"] = 1, ["name"] = "default:wood"}, {["x"] = 13, ["y"] = 3, ["z"] = 2, ["name"] = "default:wood"}, {["x"] = 13, ["y"] = 3, ["z"] = 13, ["name"] = "default:wood"}, {["x"] = 13, ["y"] = 3, ["z"] = 14, ["name"] = "default:wood"}, {["x"] = 13, ["y"] = 4, ["z"] = 1, ["name"] = "default:wood"}, {["x"] = 13, ["y"] = 4, ["z"] = 2, ["name"] = "default:wood"}, {["x"] = 13, ["y"] = 4, ["z"] = 13, ["name"] = "default:wood"}, {["x"] = 13, ["y"] = 4, ["z"] = 14, ["name"] = "default:wood"}, {["x"] = 13, ["y"] = 5, ["z"] = 1, ["name"] = "default:wood"}, {["x"] = 13, ["y"] = 5, ["z"] = 2, ["name"] = "default:wood"}, {["x"] = 13, ["y"] = 5, ["z"] = 13, ["name"] = "default:wood"}, {["x"] = 13, ["y"] = 5, ["z"] = 14, ["name"] = "default:wood"}, {["x"] = 13, ["y"] = 6, ["z"] = 1, ["name"] = "default:wood"}, {["x"] = 13, ["y"] = 6, ["z"] = 2, ["name"] = "default:wood"}, {["x"] = 13, ["y"] = 6, ["z"] = 13, ["name"] = "default:wood"}, {["x"] = 13, ["y"] = 6, ["z"] = 14, ["name"] = "default:wood"}, {["x"] = 13, ["y"] = 7, ["z"] = 1, ["name"] = "default:wood"}, {["x"] = 13, ["y"] = 7, ["z"] = 2, ["name"] = "default:wood"}, {["x"] = 13, ["y"] = 7, ["z"] = 13, ["name"] = "default:wood"}, {["x"] = 13, ["y"] = 7, ["z"] = 14, ["name"] = "default:wood"}, {["x"] = 13, ["y"] = 8, ["z"] = 1, ["name"] = "default:wood"}, {["x"] = 13, ["y"] = 8, ["z"] = 2, ["name"] = "default:wood"}, {["x"] = 13, ["y"] = 8, ["z"] = 13, ["name"] = "default:wood"}, {["x"] = 13, ["y"] = 8, ["z"] = 14, ["name"] = "default:wood"}, {["x"] = 13, ["y"] = 9, ["z"] = 0, ["name"] = "default:junglewood"}, {["x"] = 13, ["y"] = 9, ["z"] = 1, ["name"] = "default:wood"}, {["x"] = 13, ["y"] = 9, ["z"] = 2, ["name"] = "default:wood"}, {["x"] = 13, ["y"] = 9, ["z"] = 3, ["name"] = "default:junglewood"}, {["x"] = 13, ["y"] = 9, ["z"] = 4, ["name"] = "default:junglewood"}, {["x"] = 13, ["y"] = 9, ["z"] = 5, ["name"] = "default:junglewood"}, {["x"] = 13, ["y"] = 9, ["z"] = 6, ["name"] = "default:junglewood"}, {["x"] = 13, ["y"] = 9, ["z"] = 7, ["name"] = "default:junglewood"}, {["x"] = 13, ["y"] = 9, ["z"] = 8, ["name"] = "default:junglewood"}, {["x"] = 13, ["y"] = 9, ["z"] = 9, ["name"] = "default:junglewood"}, {["x"] = 13, ["y"] = 9, ["z"] = 10, ["name"] = "default:junglewood"}, {["x"] = 13, ["y"] = 9, ["z"] = 11, ["name"] = "default:junglewood"}, {["x"] = 13, ["y"] = 9, ["z"] = 12, ["name"] = "default:junglewood"}, {["x"] = 13, ["y"] = 9, ["z"] = 13, ["name"] = "default:wood"}, {["x"] = 13, ["y"] = 9, ["z"] = 14, ["name"] = "default:wood"}, {["x"] = 13, ["y"] = 9, ["z"] = 15, ["name"] = "default:junglewood"}, {["x"] = 13, ["y"] = 10, ["z"] = 0, ["name"] = "default:junglewood"}, {["x"] = 13, ["y"] = 10, ["z"] = 1, ["name"] = "default:junglewood"}, {["x"] = 13, ["y"] = 10, ["z"] = 2, ["name"] = "default:junglewood"}, {["x"] = 13, ["y"] = 10, ["z"] = 3, ["name"] = "default:junglewood"}, {["x"] = 13, ["y"] = 10, ["z"] = 4, ["name"] = "default:junglewood"}, {["x"] = 13, ["y"] = 10, ["z"] = 5, ["name"] = "default:junglewood"}, {["x"] = 13, ["y"] = 10, ["z"] = 6, ["name"] = "default:junglewood"}, {["x"] = 13, ["y"] = 10, ["z"] = 7, ["name"] = "default:junglewood"}, {["x"] = 13, ["y"] = 10, ["z"] = 8, ["name"] = "default:junglewood"}, {["x"] = 13, ["y"] = 10, ["z"] = 9, ["name"] = "default:junglewood"}, {["x"] = 13, ["y"] = 10, ["z"] = 10, ["name"] = "default:junglewood"}, {["x"] = 13, ["y"] = 10, ["z"] = 11, ["name"] = "default:junglewood"}, {["x"] = 13, ["y"] = 10, ["z"] = 12, ["name"] = "default:junglewood"}, {["x"] = 13, ["y"] = 10, ["z"] = 13, ["name"] = "default:junglewood"}, {["x"] = 13, ["y"] = 10, ["z"] = 14, ["name"] = "default:junglewood"}, {["x"] = 13, ["y"] = 10, ["z"] = 15, ["name"] = "default:junglewood"}, {["x"] = 13, ["y"] = 11, ["z"] = 1, ["name"] = "wool:white"}, {["x"] = 13, ["y"] = 11, ["z"] = 2, ["name"] = "wool:white"}, {["x"] = 13, ["y"] = 11, ["z"] = 3, ["name"] = "wool:white"}, {["x"] = 13, ["y"] = 11, ["z"] = 4, ["name"] = "wool:white"}, {["x"] = 13, ["y"] = 11, ["z"] = 5, ["name"] = "wool:white"}, {["x"] = 13, ["y"] = 12, ["z"] = 1, ["name"] = "wool:grey"}, {["x"] = 13, ["y"] = 12, ["z"] = 2, ["name"] = "wool:grey"}, {["x"] = 13, ["y"] = 12, ["z"] = 3, ["name"] = "wool:grey"}, {["x"] = 13, ["y"] = 12, ["z"] = 4, ["name"] = "wool:grey"}, {["x"] = 13, ["y"] = 12, ["z"] = 5, ["name"] = "wool:grey"}, {["x"] = 13, ["y"] = 13, ["z"] = 1, ["name"] = "wool:white"}, {["x"] = 13, ["y"] = 13, ["z"] = 2, ["name"] = "wool:white"}, {["x"] = 13, ["y"] = 13, ["z"] = 3, ["name"] = "wool:white"}, {["x"] = 13, ["y"] = 13, ["z"] = 4, ["name"] = "wool:white"}, {["x"] = 13, ["y"] = 13, ["z"] = 5, ["name"] = "wool:white"}, {["x"] = 13, ["y"] = 14, ["z"] = 1, ["name"] = "wool:grey"}, {["x"] = 13, ["y"] = 14, ["z"] = 2, ["name"] = "wool:grey"}, {["x"] = 13, ["y"] = 14, ["z"] = 3, ["name"] = "wool:grey"}, {["x"] = 13, ["y"] = 14, ["z"] = 4, ["name"] = "wool:grey"}, {["x"] = 13, ["y"] = 14, ["z"] = 5, ["name"] = "wool:grey"}, {["x"] = 13, ["y"] = 15, ["z"] = 1, ["name"] = "wool:white"}, {["x"] = 13, ["y"] = 15, ["z"] = 2, ["name"] = "wool:white"}, {["x"] = 13, ["y"] = 15, ["z"] = 3, ["name"] = "wool:white"}, {["x"] = 13, ["y"] = 15, ["z"] = 4, ["name"] = "wool:white"}, {["x"] = 13, ["y"] = 15, ["z"] = 5, ["name"] = "wool:white"}, {["x"] = 14, ["y"] = 0, ["z"] = 1, ["name"] = "default:wood"}, {["x"] = 14, ["y"] = 0, ["z"] = 2, ["name"] = "default:wood"}, {["x"] = 14, ["y"] = 0, ["z"] = 13, ["name"] = "default:wood"}, {["x"] = 14, ["y"] = 0, ["z"] = 14, ["name"] = "default:wood"}, {["x"] = 14, ["y"] = 1, ["z"] = 1, ["name"] = "default:wood"}, {["x"] = 14, ["y"] = 1, ["z"] = 2, ["name"] = "default:wood"}, {["x"] = 14, ["y"] = 1, ["z"] = 13, ["name"] = "default:wood"}, {["x"] = 14, ["y"] = 1, ["z"] = 14, ["name"] = "default:wood"}, {["x"] = 14, ["y"] = 2, ["z"] = 1, ["name"] = "default:wood"}, {["x"] = 14, ["y"] = 2, ["z"] = 2, ["name"] = "default:wood"}, {["x"] = 14, ["y"] = 2, ["z"] = 13, ["name"] = "default:wood"}, {["x"] = 14, ["y"] = 2, ["z"] = 14, ["name"] = "default:wood"}, {["x"] = 14, ["y"] = 3, ["z"] = 1, ["name"] = "default:wood"}, {["x"] = 14, ["y"] = 3, ["z"] = 2, ["name"] = "default:wood"}, {["x"] = 14, ["y"] = 3, ["z"] = 13, ["name"] = "default:wood"}, {["x"] = 14, ["y"] = 3, ["z"] = 14, ["name"] = "default:wood"}, {["x"] = 14, ["y"] = 4, ["z"] = 1, ["name"] = "default:wood"}, {["x"] = 14, ["y"] = 4, ["z"] = 2, ["name"] = "default:wood"}, {["x"] = 14, ["y"] = 4, ["z"] = 13, ["name"] = "default:wood"}, {["x"] = 14, ["y"] = 4, ["z"] = 14, ["name"] = "default:wood"}, {["x"] = 14, ["y"] = 5, ["z"] = 1, ["name"] = "default:wood"}, {["x"] = 14, ["y"] = 5, ["z"] = 2, ["name"] = "default:wood"}, {["x"] = 14, ["y"] = 5, ["z"] = 13, ["name"] = "default:wood"}, {["x"] = 14, ["y"] = 5, ["z"] = 14, ["name"] = "default:wood"}, {["x"] = 14, ["y"] = 6, ["z"] = 1, ["name"] = "default:wood"}, {["x"] = 14, ["y"] = 6, ["z"] = 2, ["name"] = "default:wood"}, {["x"] = 14, ["y"] = 6, ["z"] = 13, ["name"] = "default:wood"}, {["x"] = 14, ["y"] = 6, ["z"] = 14, ["name"] = "default:wood"}, {["x"] = 14, ["y"] = 7, ["z"] = 1, ["name"] = "default:wood"}, {["x"] = 14, ["y"] = 7, ["z"] = 2, ["name"] = "default:wood"}, {["x"] = 14, ["y"] = 7, ["z"] = 13, ["name"] = "default:wood"}, {["x"] = 14, ["y"] = 7, ["z"] = 14, ["name"] = "default:wood"}, {["x"] = 14, ["y"] = 8, ["z"] = 1, ["name"] = "default:wood"}, {["x"] = 14, ["y"] = 8, ["z"] = 2, ["name"] = "default:wood"}, {["x"] = 14, ["y"] = 8, ["z"] = 13, ["name"] = "default:wood"}, {["x"] = 14, ["y"] = 8, ["z"] = 14, ["name"] = "default:wood"}, {["x"] = 14, ["y"] = 9, ["z"] = 0, ["name"] = "default:junglewood"}, {["x"] = 14, ["y"] = 9, ["z"] = 1, ["name"] = "default:wood"}, {["x"] = 14, ["y"] = 9, ["z"] = 2, ["name"] = "default:wood"}, {["x"] = 14, ["y"] = 9, ["z"] = 3, ["name"] = "default:junglewood"}, {["x"] = 14, ["y"] = 9, ["z"] = 4, ["name"] = "default:junglewood"}, {["x"] = 14, ["y"] = 9, ["z"] = 5, ["name"] = "default:junglewood"}, {["x"] = 14, ["y"] = 9, ["z"] = 6, ["name"] = "default:junglewood"}, {["x"] = 14, ["y"] = 9, ["z"] = 7, ["name"] = "default:junglewood"}, {["x"] = 14, ["y"] = 9, ["z"] = 8, ["name"] = "default:junglewood"}, {["x"] = 14, ["y"] = 9, ["z"] = 9, ["name"] = "default:junglewood"}, {["x"] = 14, ["y"] = 9, ["z"] = 10, ["name"] = "default:junglewood"}, {["x"] = 14, ["y"] = 9, ["z"] = 11, ["name"] = "default:junglewood"}, {["x"] = 14, ["y"] = 9, ["z"] = 12, ["name"] = "default:junglewood"}, {["x"] = 14, ["y"] = 9, ["z"] = 13, ["name"] = "default:wood"}, {["x"] = 14, ["y"] = 9, ["z"] = 14, ["name"] = "default:wood"}, {["x"] = 14, ["y"] = 9, ["z"] = 15, ["name"] = "default:junglewood"}, {["x"] = 14, ["y"] = 10, ["z"] = 0, ["name"] = "default:junglewood"}, {["x"] = 14, ["y"] = 10, ["z"] = 1, ["name"] = "default:junglewood"}, {["x"] = 14, ["y"] = 10, ["z"] = 2, ["name"] = "default:junglewood"}, {["x"] = 14, ["y"] = 10, ["z"] = 3, ["name"] = "default:junglewood"}, {["x"] = 14, ["y"] = 10, ["z"] = 4, ["name"] = "default:junglewood"}, {["x"] = 14, ["y"] = 10, ["z"] = 5, ["name"] = "default:junglewood"}, {["x"] = 14, ["y"] = 10, ["z"] = 6, ["name"] = "default:junglewood"}, {["x"] = 14, ["y"] = 10, ["z"] = 7, ["name"] = "default:junglewood"}, {["x"] = 14, ["y"] = 10, ["z"] = 8, ["name"] = "default:junglewood"}, {["x"] = 14, ["y"] = 10, ["z"] = 9, ["name"] = "default:junglewood"}, {["x"] = 14, ["y"] = 10, ["z"] = 10, ["name"] = "default:junglewood"}, {["x"] = 14, ["y"] = 10, ["z"] = 11, ["name"] = "default:junglewood"}, {["x"] = 14, ["y"] = 10, ["z"] = 12, ["name"] = "default:junglewood"}, {["x"] = 14, ["y"] = 10, ["z"] = 13, ["name"] = "default:junglewood"}, {["x"] = 14, ["y"] = 10, ["z"] = 14, ["name"] = "default:junglewood"}, {["x"] = 14, ["y"] = 10, ["z"] = 15, ["name"] = "default:junglewood"}, {["x"] = 14, ["y"] = 11, ["z"] = 1, ["name"] = "wool:blue"}, {["x"] = 14, ["y"] = 11, ["z"] = 2, ["name"] = "wool:blue"}, {["x"] = 14, ["y"] = 11, ["z"] = 3, ["name"] = "wool:blue"}, {["x"] = 14, ["y"] = 11, ["z"] = 4, ["name"] = "wool:blue"}, {["x"] = 14, ["y"] = 11, ["z"] = 5, ["name"] = "wool:blue"}, {["x"] = 14, ["y"] = 12, ["z"] = 1, ["name"] = "wool:blue"}, {["x"] = 14, ["y"] = 12, ["z"] = 2, ["name"] = "wool:blue"}, {["x"] = 14, ["y"] = 12, ["z"] = 3, ["name"] = "wool:blue"}, {["x"] = 14, ["y"] = 12, ["z"] = 4, ["name"] = "wool:blue"}, {["x"] = 14, ["y"] = 12, ["z"] = 5, ["name"] = "wool:blue"}, {["x"] = 14, ["y"] = 13, ["z"] = 1, ["name"] = "wool:blue"}, {["x"] = 14, ["y"] = 13, ["z"] = 2, ["name"] = "wool:blue"}, {["x"] = 14, ["y"] = 13, ["z"] = 3, ["name"] = "wool:blue"}, {["x"] = 14, ["y"] = 13, ["z"] = 4, ["name"] = "wool:blue"}, {["x"] = 14, ["y"] = 13, ["z"] = 5, ["name"] = "wool:blue"}, {["x"] = 14, ["y"] = 14, ["z"] = 1, ["name"] = "wool:blue"}, {["x"] = 14, ["y"] = 14, ["z"] = 2, ["name"] = "wool:blue"}, {["x"] = 14, ["y"] = 14, ["z"] = 3, ["name"] = "wool:blue"}, {["x"] = 14, ["y"] = 14, ["z"] = 4, ["name"] = "wool:blue"}, {["x"] = 14, ["y"] = 14, ["z"] = 5, ["name"] = "wool:blue"}, {["x"] = 14, ["y"] = 15, ["z"] = 1, ["name"] = "wool:blue"}, {["x"] = 14, ["y"] = 15, ["z"] = 2, ["name"] = "wool:blue"}, {["x"] = 14, ["y"] = 15, ["z"] = 3, ["name"] = "wool:blue"}, {["x"] = 14, ["y"] = 15, ["z"] = 4, ["name"] = "wool:blue"}, {["x"] = 14, ["y"] = 15, ["z"] = 5, ["name"] = "wool:blue"}, {["x"] = 15, ["y"] = 9, ["z"] = 0, ["name"] = "default:junglewood"}, {["x"] = 15, ["y"] = 9, ["z"] = 1, ["name"] = "default:junglewood"}, {["x"] = 15, ["y"] = 9, ["z"] = 2, ["name"] = "default:junglewood"}, {["x"] = 15, ["y"] = 9, ["z"] = 3, ["name"] = "default:junglewood"}, {["x"] = 15, ["y"] = 9, ["z"] = 4, ["name"] = "default:junglewood"}, {["x"] = 15, ["y"] = 9, ["z"] = 5, ["name"] = "default:junglewood"}, {["x"] = 15, ["y"] = 9, ["z"] = 6, ["name"] = "default:junglewood"}, {["x"] = 15, ["y"] = 9, ["z"] = 7, ["name"] = "default:junglewood"}, {["x"] = 15, ["y"] = 9, ["z"] = 8, ["name"] = "default:junglewood"}, {["x"] = 15, ["y"] = 9, ["z"] = 9, ["name"] = "default:junglewood"}, {["x"] = 15, ["y"] = 9, ["z"] = 10, ["name"] = "default:junglewood"}, {["x"] = 15, ["y"] = 9, ["z"] = 11, ["name"] = "default:junglewood"}, {["x"] = 15, ["y"] = 9, ["z"] = 12, ["name"] = "default:junglewood"}, {["x"] = 15, ["y"] = 9, ["z"] = 13, ["name"] = "default:junglewood"}, {["x"] = 15, ["y"] = 9, ["z"] = 14, ["name"] = "default:junglewood"}, {["x"] = 15, ["y"] = 9, ["z"] = 15, ["name"] = "default:junglewood"}, {["x"] = 15, ["y"] = 10, ["z"] = 0, ["name"] = "default:junglewood"}, {["x"] = 15, ["y"] = 10, ["z"] = 1, ["name"] = "default:junglewood"}, {["x"] = 15, ["y"] = 10, ["z"] = 2, ["name"] = "default:junglewood"}, {["x"] = 15, ["y"] = 10, ["z"] = 3, ["name"] = "default:junglewood"}, {["x"] = 15, ["y"] = 10, ["z"] = 4, ["name"] = "default:junglewood"}, {["x"] = 15, ["y"] = 10, ["z"] = 5, ["name"] = "default:junglewood"}, {["x"] = 15, ["y"] = 10, ["z"] = 6, ["name"] = "default:junglewood"}, {["x"] = 15, ["y"] = 10, ["z"] = 7, ["name"] = "default:junglewood"}, {["x"] = 15, ["y"] = 10, ["z"] = 8, ["name"] = "default:junglewood"}, {["x"] = 15, ["y"] = 10, ["z"] = 9, ["name"] = "default:junglewood"}, {["x"] = 15, ["y"] = 10, ["z"] = 10, ["name"] = "default:junglewood"}, {["x"] = 15, ["y"] = 10, ["z"] = 11, ["name"] = "default:junglewood"}, {["x"] = 15, ["y"] = 10, ["z"] = 12, ["name"] = "default:junglewood"}, {["x"] = 15, ["y"] = 10, ["z"] = 13, ["name"] = "default:junglewood"}, {["x"] = 15, ["y"] = 10, ["z"] = 14, ["name"] = "default:junglewood"}, {["x"] = 15, ["y"] = 10, ["z"] = 15, ["name"] = "default:junglewood"}}